2023-06-08 11:06:56,711 ERROR: Exception on /user/mortimer/doctor/8/edit [POST] [in /home/erica/portfolio/medication_tracker/venv/lib/python3.10/site-packages/flask/app.py:1744]
Traceback (most recent call last):
  File "/home/erica/portfolio/medication_tracker/venv/lib/python3.10/site-packages/flask/app.py", line 2528, in wsgi_app
    response = self.full_dispatch_request()
  File "/home/erica/portfolio/medication_tracker/venv/lib/python3.10/site-packages/flask/app.py", line 1825, in full_dispatch_request
    rv = self.handle_user_exception(e)
  File "/home/erica/portfolio/medication_tracker/venv/lib/python3.10/site-packages/flask/app.py", line 1823, in full_dispatch_request
    rv = self.dispatch_request()
  File "/home/erica/portfolio/medication_tracker/venv/lib/python3.10/site-packages/flask/app.py", line 1799, in dispatch_request
    return self.ensure_sync(self.view_functions[rule.endpoint])(**view_args)
  File "/home/erica/portfolio/medication_tracker/venv/lib/python3.10/site-packages/flask_login/utils.py", line 290, in decorated_view
    return current_app.ensure_sync(func)(*args, **kwargs)
  File "/home/erica/portfolio/medication_tracker/app/main/routes.py", line 305, in edit_doctor
    if form.validate_on_submit():
  File "/home/erica/portfolio/medication_tracker/venv/lib/python3.10/site-packages/flask_wtf/form.py", line 86, in validate_on_submit
    return self.is_submitted() and self.validate(extra_validators=extra_validators)
  File "/home/erica/portfolio/medication_tracker/venv/lib/python3.10/site-packages/wtforms/form.py", line 329, in validate
    return super().validate(extra)
  File "/home/erica/portfolio/medication_tracker/venv/lib/python3.10/site-packages/wtforms/form.py", line 146, in validate
    if not field.validate(self, extra):
  File "/home/erica/portfolio/medication_tracker/venv/lib/python3.10/site-packages/wtforms/fields/core.py", line 242, in validate
    stop_validation = self._run_validation_chain(form, chain)
  File "/home/erica/portfolio/medication_tracker/venv/lib/python3.10/site-packages/wtforms/fields/core.py", line 262, in _run_validation_chain
    validator(form, self)
  File "/home/erica/portfolio/medication_tracker/venv/lib/python3.10/site-packages/wtforms/validators.py", line 138, in __call__
    length = field.data and len(field.data) or 0
TypeError: object of type 'int' has no len()
2023-06-08 11:10:02,382 INFO: Medication tracker startup [in /home/erica/portfolio/medication_tracker/app/__init__.py:64]
2023-06-08 11:11:10,847 INFO: Medication tracker startup [in /home/erica/portfolio/medication_tracker/app/__init__.py:64]
2023-06-08 11:12:14,159 INFO: Medication tracker startup [in /home/erica/portfolio/medication_tracker/app/__init__.py:64]
2023-06-08 11:12:19,143 ERROR: Exception on /user/mortimer/doctor/8/edit [POST] [in /home/erica/portfolio/medication_tracker/venv/lib/python3.10/site-packages/flask/app.py:1744]
Traceback (most recent call last):
  File "/home/erica/portfolio/medication_tracker/venv/lib/python3.10/site-packages/flask/app.py", line 2528, in wsgi_app
    response = self.full_dispatch_request()
  File "/home/erica/portfolio/medication_tracker/venv/lib/python3.10/site-packages/flask/app.py", line 1825, in full_dispatch_request
    rv = self.handle_user_exception(e)
  File "/home/erica/portfolio/medication_tracker/venv/lib/python3.10/site-packages/flask/app.py", line 1823, in full_dispatch_request
    rv = self.dispatch_request()
  File "/home/erica/portfolio/medication_tracker/venv/lib/python3.10/site-packages/flask/app.py", line 1799, in dispatch_request
    return self.ensure_sync(self.view_functions[rule.endpoint])(**view_args)
  File "/home/erica/portfolio/medication_tracker/venv/lib/python3.10/site-packages/flask_login/utils.py", line 290, in decorated_view
    return current_app.ensure_sync(func)(*args, **kwargs)
  File "/home/erica/portfolio/medication_tracker/app/main/routes.py", line 305, in edit_doctor
    if form.validate_on_submit():
  File "/home/erica/portfolio/medication_tracker/venv/lib/python3.10/site-packages/flask_wtf/form.py", line 86, in validate_on_submit
    return self.is_submitted() and self.validate(extra_validators=extra_validators)
  File "/home/erica/portfolio/medication_tracker/venv/lib/python3.10/site-packages/wtforms/form.py", line 329, in validate
    return super().validate(extra)
  File "/home/erica/portfolio/medication_tracker/venv/lib/python3.10/site-packages/wtforms/form.py", line 146, in validate
    if not field.validate(self, extra):
  File "/home/erica/portfolio/medication_tracker/venv/lib/python3.10/site-packages/wtforms/fields/core.py", line 242, in validate
    stop_validation = self._run_validation_chain(form, chain)
  File "/home/erica/portfolio/medication_tracker/venv/lib/python3.10/site-packages/wtforms/fields/core.py", line 262, in _run_validation_chain
    validator(form, self)
  File "/home/erica/portfolio/medication_tracker/app/main/forms.py", line 273, in validate_doctor_zipcode
    if len(doctor_zipcode) < 5:
TypeError: object of type 'StringField' has no len()
2023-06-08 11:12:47,412 INFO: Medication tracker startup [in /home/erica/portfolio/medication_tracker/app/__init__.py:64]
2023-06-08 11:16:34,568 INFO: Medication tracker startup [in /home/erica/portfolio/medication_tracker/app/__init__.py:64]
2023-06-08 11:17:00,333 INFO: Medication tracker startup [in /home/erica/portfolio/medication_tracker/app/__init__.py:64]
2023-06-08 11:18:22,647 INFO: Medication tracker startup [in /home/erica/portfolio/medication_tracker/app/__init__.py:64]
2023-06-08 11:22:56,591 INFO: Medication tracker startup [in /home/erica/portfolio/medication_tracker/app/__init__.py:64]
2023-06-08 11:23:08,166 ERROR: Exception on /user/mortimer/pharmacy/3/edit [POST] [in /home/erica/portfolio/medication_tracker/venv/lib/python3.10/site-packages/flask/app.py:1744]
Traceback (most recent call last):
  File "/home/erica/portfolio/medication_tracker/venv/lib/python3.10/site-packages/flask/app.py", line 2528, in wsgi_app
    response = self.full_dispatch_request()
  File "/home/erica/portfolio/medication_tracker/venv/lib/python3.10/site-packages/flask/app.py", line 1826, in full_dispatch_request
    return self.finalize_request(rv)
  File "/home/erica/portfolio/medication_tracker/venv/lib/python3.10/site-packages/flask/app.py", line 1845, in finalize_request
    response = self.make_response(rv)
  File "/home/erica/portfolio/medication_tracker/venv/lib/python3.10/site-packages/flask/app.py", line 2137, in make_response
    raise TypeError(
TypeError: The view function for 'main.edit_pharmacy' did not return a valid response. The function either returned None or ended without a return statement.
2023-06-08 11:23:23,041 INFO: Medication tracker startup [in /home/erica/portfolio/medication_tracker/app/__init__.py:64]
