2023-06-06 17:52:47,011 ERROR: Exception on /auth/reset_password_request [GET] [in /home/erica/.local/lib/python3.10/site-packages/flask/app.py:1741]
Traceback (most recent call last):
  File "/home/erica/.local/lib/python3.10/site-packages/flask/app.py", line 2525, in wsgi_app
    response = self.full_dispatch_request()
  File "/home/erica/.local/lib/python3.10/site-packages/flask/app.py", line 1822, in full_dispatch_request
    rv = self.handle_user_exception(e)
  File "/home/erica/.local/lib/python3.10/site-packages/flask/app.py", line 1820, in full_dispatch_request
    rv = self.dispatch_request()
  File "/home/erica/.local/lib/python3.10/site-packages/flask/app.py", line 1796, in dispatch_request
    return self.ensure_sync(self.view_functions[rule.endpoint])(**view_args)
  File "/home/erica/portfolio/medication_tracker/app/auth/routes.py", line 77, in reset_password_request
    return render_template('auth/reset_password_request.html',
  File "/home/erica/.local/lib/python3.10/site-packages/flask/templating.py", line 146, in render_template
    template = app.jinja_env.get_or_select_template(template_name_or_list)
  File "/home/erica/.local/lib/python3.10/site-packages/jinja2/environment.py", line 1081, in get_or_select_template
    return self.get_template(template_name_or_list, parent, globals)
  File "/home/erica/.local/lib/python3.10/site-packages/jinja2/environment.py", line 1010, in get_template
    return self._load_template(name, globals)
  File "/home/erica/.local/lib/python3.10/site-packages/jinja2/environment.py", line 969, in _load_template
    template = self.loader.load(self, name, self.make_globals(globals))
  File "/home/erica/.local/lib/python3.10/site-packages/jinja2/loaders.py", line 138, in load
    code = environment.compile(source, name, filename)
  File "/home/erica/.local/lib/python3.10/site-packages/jinja2/environment.py", line 768, in compile
    self.handle_exception(source=source_hint)
  File "/home/erica/.local/lib/python3.10/site-packages/jinja2/environment.py", line 936, in handle_exception
    raise rewrite_traceback_stack(source=source)
  File "/home/erica/portfolio/medication_tracker/app/templates/auth/reset_password_request.html", line 24, in template
    <span style="color: red;">[{{{ error }}}]</span>
jinja2.exceptions.TemplateSyntaxError: expected token ':', got '}'
2023-06-06 17:53:39,760 INFO: Medication tracker startup [in /home/erica/portfolio/medication_tracker/app/__init__.py:63]
2023-06-06 17:53:50,784 ERROR: Exception on /auth/reset_password_request [POST] [in /home/erica/.local/lib/python3.10/site-packages/flask/app.py:1741]
Traceback (most recent call last):
  File "/home/erica/.local/lib/python3.10/site-packages/flask/app.py", line 2525, in wsgi_app
    response = self.full_dispatch_request()
  File "/home/erica/.local/lib/python3.10/site-packages/flask/app.py", line 1822, in full_dispatch_request
    rv = self.handle_user_exception(e)
  File "/home/erica/.local/lib/python3.10/site-packages/flask/app.py", line 1820, in full_dispatch_request
    rv = self.dispatch_request()
  File "/home/erica/.local/lib/python3.10/site-packages/flask/app.py", line 1796, in dispatch_request
    return self.ensure_sync(self.view_functions[rule.endpoint])(**view_args)
  File "/home/erica/portfolio/medication_tracker/app/auth/routes.py", line 74, in reset_password_request
    send_password_reset_email(user)
  File "/home/erica/portfolio/medication_tracker/app/auth/email.py", line 6, in send_password_reset_email
    token = user.get_reset_password_token()
  File "/home/erica/portfolio/medication_tracker/app/models.py", line 30, in get_reset_password_token
    app.config['SECRET_KEY'], algorithm='HS256')
NameError: name 'app' is not defined
2023-06-06 17:55:19,778 INFO: Medication tracker startup [in /home/erica/portfolio/medication_tracker/app/__init__.py:63]
2023-06-06 17:55:26,230 ERROR: Exception on /auth/reset_password_request [POST] [in /home/erica/.local/lib/python3.10/site-packages/flask/app.py:1741]
Traceback (most recent call last):
  File "/home/erica/.local/lib/python3.10/site-packages/flask/app.py", line 2525, in wsgi_app
    response = self.full_dispatch_request()
  File "/home/erica/.local/lib/python3.10/site-packages/flask/app.py", line 1822, in full_dispatch_request
    rv = self.handle_user_exception(e)
  File "/home/erica/.local/lib/python3.10/site-packages/flask/app.py", line 1820, in full_dispatch_request
    rv = self.dispatch_request()
  File "/home/erica/.local/lib/python3.10/site-packages/flask/app.py", line 1796, in dispatch_request
    return self.ensure_sync(self.view_functions[rule.endpoint])(**view_args)
  File "/home/erica/portfolio/medication_tracker/app/auth/routes.py", line 74, in reset_password_request
    send_password_reset_email(user)
  File "/home/erica/portfolio/medication_tracker/app/auth/email.py", line 8, in send_password_reset_email
    sender=app.config['ADMINS'][0],
NameError: name 'app' is not defined
2023-06-06 17:56:16,480 INFO: Medication tracker startup [in /home/erica/portfolio/medication_tracker/app/__init__.py:63]
2023-06-06 17:56:22,617 ERROR: Exception on /auth/reset_password_request [POST] [in /home/erica/.local/lib/python3.10/site-packages/flask/app.py:1741]
Traceback (most recent call last):
  File "/home/erica/.local/lib/python3.10/site-packages/flask_mail.py", line 508, in connect
    return Connection(app.extensions['mail'])
KeyError: 'mail'

During handling of the above exception, another exception occurred:

Traceback (most recent call last):
  File "/home/erica/.local/lib/python3.10/site-packages/flask/app.py", line 2525, in wsgi_app
    response = self.full_dispatch_request()
  File "/home/erica/.local/lib/python3.10/site-packages/flask/app.py", line 1822, in full_dispatch_request
    rv = self.handle_user_exception(e)
  File "/home/erica/.local/lib/python3.10/site-packages/flask/app.py", line 1820, in full_dispatch_request
    rv = self.dispatch_request()
  File "/home/erica/.local/lib/python3.10/site-packages/flask/app.py", line 1796, in dispatch_request
    return self.ensure_sync(self.view_functions[rule.endpoint])(**view_args)
  File "/home/erica/portfolio/medication_tracker/app/auth/routes.py", line 74, in reset_password_request
    send_password_reset_email(user)
  File "/home/erica/portfolio/medication_tracker/app/auth/email.py", line 7, in send_password_reset_email
    send_email('Reset Your Password',
  File "/home/erica/portfolio/medication_tracker/app/email.py", line 8, in send_email
    mail.send(msg)
  File "/home/erica/.local/lib/python3.10/site-packages/flask_mail.py", line 491, in send
    with self.connect() as connection:
  File "/home/erica/.local/lib/python3.10/site-packages/flask_mail.py", line 510, in connect
    raise RuntimeError("The curent application was not configured with Flask-Mail")
RuntimeError: The curent application was not configured with Flask-Mail
2023-06-06 18:00:24,210 INFO: Medication tracker startup [in /home/erica/portfolio/medication_tracker/app/__init__.py:63]
2023-06-06 18:00:35,322 ERROR: Exception on /auth/reset_password_request [POST] [in /home/erica/.local/lib/python3.10/site-packages/flask/app.py:1741]
Traceback (most recent call last):
  File "/home/erica/.local/lib/python3.10/site-packages/flask_mail.py", line 508, in connect
    return Connection(app.extensions['mail'])
KeyError: 'mail'

During handling of the above exception, another exception occurred:

Traceback (most recent call last):
  File "/home/erica/.local/lib/python3.10/site-packages/flask/app.py", line 2525, in wsgi_app
    response = self.full_dispatch_request()
  File "/home/erica/.local/lib/python3.10/site-packages/flask/app.py", line 1822, in full_dispatch_request
    rv = self.handle_user_exception(e)
  File "/home/erica/.local/lib/python3.10/site-packages/flask/app.py", line 1820, in full_dispatch_request
    rv = self.dispatch_request()
  File "/home/erica/.local/lib/python3.10/site-packages/flask/app.py", line 1796, in dispatch_request
    return self.ensure_sync(self.view_functions[rule.endpoint])(**view_args)
  File "/home/erica/portfolio/medication_tracker/app/auth/routes.py", line 74, in reset_password_request
    send_password_reset_email(user)
  File "/home/erica/portfolio/medication_tracker/app/auth/email.py", line 7, in send_password_reset_email
    send_email('Reset Your Password',
  File "/home/erica/portfolio/medication_tracker/app/email.py", line 8, in send_email
    mail.send(msg)
  File "/home/erica/.local/lib/python3.10/site-packages/flask_mail.py", line 491, in send
    with self.connect() as connection:
  File "/home/erica/.local/lib/python3.10/site-packages/flask_mail.py", line 510, in connect
    raise RuntimeError("The curent application was not configured with Flask-Mail")
RuntimeError: The curent application was not configured with Flask-Mail
2023-06-06 18:09:51,189 INFO: Medication tracker startup [in /home/erica/portfolio/medication_tracker/app/__init__.py:64]
